<?xml version="1.0" ?>
<!--
SPDX-FileCopyrightText: 2026, FANUC America Corporation
SPDX-FileCopyrightText: 2026, FANUC CORPORATION
SPDX-License-Identifier: Apache-2.0
-->
<!-- URDF for M-710/50-26D (M-710iD/50M) -->
<robot xmlns:xacro="http://wiki.ros.org/xacro">
  <xacro:macro
    name="m710id_50m"
    params="prefix=''
            parent
            *origin
            child"
  >

    <xacro:property name="j1_lower_limit" value="${radians(-185)}" />
    <xacro:property name="j2_lower_limit" value="${radians(-75)}" />
    <xacro:property name="j3_lower_limit" value="${radians(-80.5)}" />
    <xacro:property name="j4_lower_limit" value="${radians(-400)}" />
    <xacro:property name="j5_lower_limit" value="${radians(-125)}" />
    <xacro:property name="j6_lower_limit" value="${radians(-400)}" />

    <xacro:property name="j1_upper_limit" value="${radians(185)}" />
    <xacro:property name="j2_upper_limit" value="${radians(150)}" />
    <xacro:property name="j3_upper_limit" value="${radians(205)}" />
    <xacro:property name="j4_upper_limit" value="${radians(400)}" />
    <xacro:property name="j5_upper_limit" value="${radians(125)}" />
    <xacro:property name="j6_upper_limit" value="${radians(400)}" />

    <xacro:property name="j1_effort_limit" value="8000" />
    <xacro:property name="j2_effort_limit" value="10000" />
    <xacro:property name="j3_effort_limit" value="5000" />
    <xacro:property name="j4_effort_limit" value="2000" />
    <xacro:property name="j5_effort_limit" value="1000" />
    <xacro:property name="j6_effort_limit" value="900" />

    <xacro:property name="j1_velocity_limit" value="${radians(180)}" />
    <xacro:property name="j2_velocity_limit" value="${radians(180)}" />
    <xacro:property name="j3_velocity_limit" value="${radians(180)}" />
    <xacro:property name="j4_velocity_limit" value="${radians(260)}" />
    <xacro:property name="j5_velocity_limit" value="${radians(260)}" />
    <xacro:property name="j6_velocity_limit" value="${radians(370)}" />

    <!-- links -->
    <link name="${prefix}base_link">
      <visual>
        <origin xyz="0 0 0" rpy="0 0 0" />
        <geometry>
          <mesh
            filename="package://fanuc_m710_description/meshes/m710id_50m/visual/base.dae"
          />
        </geometry>
      </visual>
      <collision>
        <origin xyz="0 0 0" rpy="0 0 0" />
        <geometry>
          <mesh
            filename="package://fanuc_m710_description/meshes/m710id_50m/collision/base.stl"
          />
        </geometry>
      </collision>
      <inertial>
        <mass value=" 109" />
        <origin xyz="-.0562 -.000509  .109" />
        <inertia
          ixx=" 2.8"
          ixy="-.0329"
          ixz=" .025"
          iyy=" 3"
          iyz=" .00163"
          izz=" 4.87"
        />
      </inertial>
    </link>

    <link name="${prefix}J1_link">
      <visual>
        <origin xyz="0 0 0" rpy="0 0 0" />
        <geometry>
          <mesh
            filename="package://fanuc_m710_description/meshes/m710id_50m/visual/j1.dae"
          />
        </geometry>
      </visual>
      <collision>
        <origin xyz="0 0 0" rpy="0 0 0" />
        <geometry>
          <mesh
            filename="package://fanuc_m710_description/meshes/m710id_50m/collision/j1.stl"
          />
        </geometry>
      </collision>
      <inertial>
        <mass value=" 180" />
        <origin xyz=" .0361 -.00381 -.0873" />
        <inertia
          ixx=" 6.87"
          ixy=" .225"
          ixz="-.615"
          iyy=" 5.55"
          iyz=" .424"
          izz=" 7.07"
        />
      </inertial>
    </link>

    <link name="${prefix}J2_link">
      <visual>
        <origin xyz="0 0 0" rpy="0 0 0" />
        <geometry>
          <mesh
            filename="package://fanuc_m710_description/meshes/m710id_50m/visual/j2.dae"
          />
        </geometry>
      </visual>
      <collision>
        <origin xyz="0 0 0" rpy="0 0 0" />
        <geometry>
          <mesh
            filename="package://fanuc_m710_description/meshes/m710id_50m/collision/j2.stl"
          />
        </geometry>
      </collision>
      <inertial>
        <mass value=" 167" />
        <origin xyz="-.035  .173  .519" />
        <inertia
          ixx=" 24.1"
          ixy=" .149"
          ixz=" .00551"
          iyy=" 25.3"
          iyz="-1.58"
          izz=" 2.46"
        />
      </inertial>
    </link>

    <link name="${prefix}J3_link">
      <visual>
        <origin xyz="0 0 0" rpy="0 0 0" />
        <geometry>
          <mesh
            filename="package://fanuc_m710_description/meshes/m710id_50m/visual/j3.dae"
          />
        </geometry>
      </visual>
      <collision>
        <origin xyz="0 0 0" rpy="0 0 0" />
        <geometry>
          <mesh
            filename="package://fanuc_m710_description/meshes/m710id_50m/collision/j3.stl"
          />
        </geometry>
      </collision>
      <inertial>
        <mass value=" 89.4" />
        <origin xyz=" .0255 -.005  .0679" />
        <inertia
          ixx=" 1.9"
          ixy="-.0775"
          ixz="-.311"
          iyy=" 2.41"
          iyz="-.06"
          izz=" 1.92"
        />
      </inertial>
    </link>

    <link name="${prefix}J4_link">
      <visual>
        <origin xyz="0 0 0" rpy="0 0 0" />
        <geometry>
          <mesh
            filename="package://fanuc_m710_description/meshes/m710id_50m/visual/j4.dae"
          />
        </geometry>
      </visual>
      <collision>
        <origin xyz="0 0 0" rpy="0 0 0" />
        <geometry>
          <mesh
            filename="package://fanuc_m710_description/meshes/m710id_50m/collision/j4.stl"
          />
        </geometry>
      </collision>
      <inertial>
        <mass value=" 44.2" />
        <origin xyz=" .722 -.00464  .0000825" />
        <inertia
          ixx=" .181"
          ixy=" .0138"
          ixz=" .0000199"
          iyy=" 3.93"
          iyz="-.000138"
          izz=" 3.93"
        />
      </inertial>
    </link>

    <link name="${prefix}J5_link">
      <visual>
        <origin xyz="0 0 0" rpy="0 0 0" />
        <geometry>
          <mesh
            filename="package://fanuc_m710_description/meshes/m710id_50m/visual/j5.dae"
          />
        </geometry>
      </visual>
      <collision>
        <origin xyz="0 0 0" rpy="0 0 0" />
        <geometry>
          <mesh
            filename="package://fanuc_m710_description/meshes/m710id_50m/collision/j5.stl"
          />
        </geometry>
      </collision>
      <inertial>
        <mass value=" 9.67" />
        <origin xyz=" .0325 -.0138  .000000624" />
        <inertia
          ixx=" .0432"
          ixy="-.00522"
          ixz="-.000000315"
          iyy=" .0487"
          iyz="-.0000000877"
          izz=" .0633"
        />
      </inertial>
    </link>

    <link name="${prefix}J6_link">
      <visual>
        <origin xyz="0 0 0" rpy="0 0 0" />
        <geometry>
          <mesh
            filename="package://fanuc_m710_description/meshes/m710id_50m/visual/j6.dae"
          />
        </geometry>
      </visual>
      <collision>
        <origin xyz="0 0 0" rpy="0 0 0" />
        <geometry>
          <mesh
            filename="package://fanuc_m710_description/meshes/m710id_50m/collision/j6.stl"
          />
        </geometry>
      </collision>
      <inertial>
        <mass value=" .415" />
        <origin xyz=" .165  4.54E-18  2.83E-18" />
        <inertia
          ixx=" .000809"
          ixy=" 1.32E-19"
          ixz=" 3E-19"
          iyy=" .000417"
          iyz=" .0000000000746"
          izz=" .000417"
        />
      </inertial>
    </link>

    <!-- joints -->
    <joint name="${prefix}J1" type="revolute">
      <origin xyz=" 0  0  .565" rpy="0 0 0" />
      <parent link="${prefix}base_link" />
      <child link="${prefix}J1_link" />
      <axis xyz=" 0  0  1" />
      <limit
        lower="${j1_lower_limit}"
        upper="${j1_upper_limit}"
        effort="${j1_effort_limit}"
        velocity="${j1_velocity_limit}"
      />
    </joint>

    <joint name="${prefix}J2" type="revolute">
      <origin xyz=" .15  0  0" rpy="0 0 0" />
      <parent link="${prefix}J1_link" />
      <child link="${prefix}J2_link" />
      <axis xyz=" 0  1  0" />
      <limit
        lower="${j2_lower_limit}"
        upper="${j2_upper_limit}"
        effort="${j2_effort_limit}"
        velocity="${j2_velocity_limit}"
      />
    </joint>

    <joint name="${prefix}J3" type="revolute">
      <origin xyz=" 0  0  1.15" rpy="0 0 0" />
      <parent link="${prefix}J2_link" />
      <child link="${prefix}J3_link" />
      <axis xyz=" 0 -1  0" />
      <limit
        lower="${j3_lower_limit}"
        upper="${j3_upper_limit}"
        effort="${j3_effort_limit}"
        velocity="${j3_velocity_limit}"
      />
    </joint>

    <joint name="${prefix}J4" type="revolute">
      <origin xyz=" 0  0  .17" rpy="0 0 0" />
      <parent link="${prefix}J3_link" />
      <child link="${prefix}J4_link" />
      <axis xyz="-1  0  0" />
      <limit
        lower="${j4_lower_limit}"
        upper="${j4_upper_limit}"
        effort="${j4_effort_limit}"
        velocity="${j4_velocity_limit}"
      />
    </joint>

    <joint name="${prefix}J5" type="revolute">
      <origin xyz=" 1.295  0  0" rpy="0 0 0" />
      <parent link="${prefix}J4_link" />
      <child link="${prefix}J5_link" />
      <axis xyz=" 0 -1  0" />
      <limit
        lower="${j5_lower_limit}"
        upper="${j5_upper_limit}"
        effort="${j5_effort_limit}"
        velocity="${j5_velocity_limit}"
      />
    </joint>

    <joint name="${prefix}J6" type="revolute">
      <origin xyz=" 0  0  0" rpy="0 0 0" />
      <parent link="${prefix}J5_link" />
      <child link="${prefix}J6_link" />
      <axis xyz="-1  0  0" />
      <limit
        lower="${j6_lower_limit}"
        upper="${j6_upper_limit}"
        effort="${j6_effort_limit}"
        velocity="${j6_velocity_limit}"
      />
    </joint>

    <!-- world coords -->
    <link name="${prefix}wbase" />
    <joint name="${prefix}base_link-wbase" type="fixed">
      <origin xyz=" 0  0  .565" rpy="0 0 0" />
      <parent link="${prefix}base_link" />
      <child link="${prefix}wbase" />
    </joint>

    <!-- flange coords -->
    <link name="${prefix}flange" />
    <joint name="${prefix}J6-flange" type="fixed">
      <origin xyz=" .175  0  0" rpy="0 0 0" />
      <parent link="${prefix}J6_link" />
      <child link="${prefix}flange" />
    </joint>

    <!-- FANUC flange coords -->
    <link name="${prefix}fanuc_flange" />
    <joint name="${prefix}flange-fanuc_flange" type="fixed">
      <origin xyz="0 0 0" rpy="${radians( 180)} ${radians(-90)} ${radians( 0)}" />
      <parent link="${prefix}flange" />
      <child link="${prefix}fanuc_flange" />
    </joint>

    <!-- Attach to parent -->
    <joint name="${prefix}base_joint" type="fixed">
      <xacro:insert_block name="origin" />
      <parent link="${parent}" />
      <child link="${prefix}base_link" />
    </joint>

    <!-- Attach child -->
    <joint name="${prefix}child_joint" type="fixed">
      <origin xyz="0 0 0" rpy="0 0 0" />
      <parent link="${prefix}flange" />
      <child link="${child}" />
    </joint>
  </xacro:macro>
</robot>
