<?xml version="1.0" ?>
<!--
SPDX-FileCopyrightText: 2026, FANUC America Corporation
SPDX-FileCopyrightText: 2026, FANUC CORPORATION
SPDX-License-Identifier: Apache-2.0
-->
<!-- URDF for M-710iC/45M -->
<robot xmlns:xacro="http://wiki.ros.org/xacro">
  <xacro:macro
    name="m710ic_45m"
    params="prefix=''
            parent
            *origin
            child"
  >

    <xacro:property name="j1_lower_limit" value="${radians(-180)}" />
    <xacro:property name="j2_lower_limit" value="${radians(-90)}" />
    <xacro:property name="j3_lower_limit" value="${radians(-80.5)}" />
    <xacro:property name="j4_lower_limit" value="${radians(-400)}" />
    <xacro:property name="j5_lower_limit" value="${radians(-125)}" />
    <xacro:property name="j6_lower_limit" value="${radians(-400)}" />

    <xacro:property name="j1_upper_limit" value="${radians(180)}" />
    <xacro:property name="j2_upper_limit" value="${radians(135)}" />
    <xacro:property name="j3_upper_limit" value="${radians(205)}" />
    <xacro:property name="j4_upper_limit" value="${radians(400)}" />
    <xacro:property name="j5_upper_limit" value="${radians(125)}" />
    <xacro:property name="j6_upper_limit" value="${radians(400)}" />

    <xacro:property name="j1_effort_limit" value="9000" />
    <xacro:property name="j2_effort_limit" value="9000" />
    <xacro:property name="j3_effort_limit" value="4000" />
    <xacro:property name="j4_effort_limit" value="800" />
    <xacro:property name="j5_effort_limit" value="900" />
    <xacro:property name="j6_effort_limit" value="700" />

    <xacro:property name="j1_velocity_limit" value="${radians(180)}" />
    <xacro:property name="j2_velocity_limit" value="${radians(180)}" />
    <xacro:property name="j3_velocity_limit" value="${radians(180)}" />
    <xacro:property name="j4_velocity_limit" value="${radians(250)}" />
    <xacro:property name="j5_velocity_limit" value="${radians(250)}" />
    <xacro:property name="j6_velocity_limit" value="${radians(360)}" />

    <!-- links -->
    <link name="${prefix}base_link">
      <visual>
        <origin xyz="0 0 0" rpy="0 0 0" />
        <geometry>
          <mesh
            filename="package://fanuc_m710_description/meshes/m710ic_45m/visual/base.dae"
          />
        </geometry>
      </visual>
      <collision>
        <origin xyz="0 0 0" rpy="0 0 0" />
        <geometry>
          <mesh
            filename="package://fanuc_m710_description/meshes/m710ic_45m/collision/base.stl"
          />
        </geometry>
      </collision>
      <inertial>
        <mass value=" 128" />
        <origin xyz="-.0566 -.000891  .119" />
        <inertia
          ixx=" 3.37"
          ixy="-.0143"
          ixz=" .0419"
          iyy=" 3.64"
          iyz="-.00664"
          izz=" 5.68"
        />
      </inertial>
    </link>

    <link name="${prefix}J1_link">
      <visual>
        <origin xyz="0 0 0" rpy="0 0 0" />
        <geometry>
          <mesh
            filename="package://fanuc_m710_description/meshes/m710ic_45m/visual/j1.dae"
          />
        </geometry>
      </visual>
      <collision>
        <origin xyz="0 0 0" rpy="0 0 0" />
        <geometry>
          <mesh
            filename="package://fanuc_m710_description/meshes/m710ic_45m/collision/j1.stl"
          />
        </geometry>
      </collision>
      <inertial>
        <mass value=" 192" />
        <origin xyz=" .0514 -.00698 -.104" />
        <inertia
          ixx=" 7.14"
          ixy="-.31"
          ixz="-.501"
          iyy=" 6.1"
          iyz=" .208"
          izz=" 7.66"
        />
      </inertial>
    </link>

    <link name="${prefix}J2_link">
      <visual>
        <origin xyz="0 0 0" rpy="0 0 0" />
        <geometry>
          <mesh
            filename="package://fanuc_m710_description/meshes/m710ic_45m/visual/j2.dae"
          />
        </geometry>
      </visual>
      <collision>
        <origin xyz="0 0 0" rpy="0 0 0" />
        <geometry>
          <mesh
            filename="package://fanuc_m710_description/meshes/m710ic_45m/collision/j2.stl"
          />
        </geometry>
      </collision>
      <inertial>
        <mass value=" 109" />
        <origin xyz=" .00255  .155  .462" />
        <inertia
          ixx=" 15"
          ixy=" .025"
          ixz=" .0168"
          iyy=" 15.3"
          iyz="-.483"
          izz=" .901"
        />
      </inertial>
    </link>

    <link name="${prefix}J3_link">
      <visual>
        <origin xyz="0 0 0" rpy="0 0 0" />
        <geometry>
          <mesh
            filename="package://fanuc_m710_description/meshes/m710ic_45m/visual/j3.dae"
          />
        </geometry>
      </visual>
      <collision>
        <origin xyz="0 0 0" rpy="0 0 0" />
        <geometry>
          <mesh
            filename="package://fanuc_m710_description/meshes/m710ic_45m/collision/j3.stl"
          />
        </geometry>
      </collision>
      <inertial>
        <mass value=" 87.5" />
        <origin xyz=" .0116 -.0318  .0851" />
        <inertia
          ixx=" 1.71"
          ixy="-.159"
          ixz="-.191"
          iyy=" 2.07"
          iyz="-.0869"
          izz=" 1.86"
        />
      </inertial>
    </link>

    <link name="${prefix}J4_link">
      <visual>
        <origin xyz="0 0 0" rpy="0 0 0" />
        <geometry>
          <mesh
            filename="package://fanuc_m710_description/meshes/m710ic_45m/visual/j4.dae"
          />
        </geometry>
      </visual>
      <collision>
        <origin xyz="0 0 0" rpy="0 0 0" />
        <geometry>
          <mesh
            filename="package://fanuc_m710_description/meshes/m710ic_45m/collision/j4.stl"
          />
        </geometry>
      </collision>
      <inertial>
        <mass value=" 44.7" />
        <origin xyz=" .806 -.0208  .000409" />
        <inertia
          ixx=" .165"
          ixy=" .181"
          ixz="-.00166"
          iyy=" 4.44"
          iyz="-.000577"
          izz=" 4.46"
        />
      </inertial>
    </link>

    <link name="${prefix}J5_link">
      <visual>
        <origin xyz="0 0 0" rpy="0 0 0" />
        <geometry>
          <mesh
            filename="package://fanuc_m710_description/meshes/m710ic_45m/visual/j5.dae"
          />
        </geometry>
      </visual>
      <collision>
        <origin xyz="0 0 0" rpy="0 0 0" />
        <geometry>
          <mesh
            filename="package://fanuc_m710_description/meshes/m710ic_45m/collision/j5.stl"
          />
        </geometry>
      </collision>
      <inertial>
        <mass value=" 8.95" />
        <origin xyz=" .0404  .00391 -.00000114" />
        <inertia
          ixx=" .0332"
          ixy="-.00257"
          ixz=" .000000378"
          iyy=" .0476"
          iyz="-.000000339"
          izz=" .0505"
        />
      </inertial>
    </link>

    <link name="${prefix}J6_link">
      <visual>
        <origin xyz="0 0 0" rpy="0 0 0" />
        <geometry>
          <mesh
            filename="package://fanuc_m710_description/meshes/m710ic_45m/visual/j6.dae"
          />
        </geometry>
      </visual>
      <collision>
        <origin xyz="0 0 0" rpy="0 0 0" />
        <geometry>
          <mesh
            filename="package://fanuc_m710_description/meshes/m710ic_45m/collision/j6.stl"
          />
        </geometry>
      </collision>
      <inertial>
        <mass value=" .463" />
        <origin xyz=" .165 -4.6E-18 -1.29E-18" />
        <inertia
          ixx=" .000898"
          ixy="-1.24E-18"
          ixz="-1.44E-19"
          iyy=" .000465"
          iyz=" .0000000000662"
          izz=" .000465"
        />
      </inertial>
    </link>

    <!-- joints -->
    <joint name="${prefix}J1" type="revolute">
      <origin xyz=" 0  0  .565" rpy="0 0 0" />
      <parent link="${prefix}base_link" />
      <child link="${prefix}J1_link" />
      <axis xyz=" 0  0  1" />
      <limit
        lower="${j1_lower_limit}"
        upper="${j1_upper_limit}"
        effort="${j1_effort_limit}"
        velocity="${j1_velocity_limit}"
      />
    </joint>

    <joint name="${prefix}J2" type="revolute">
      <origin xyz=" .15  0  0" rpy="0 0 0" />
      <parent link="${prefix}J1_link" />
      <child link="${prefix}J2_link" />
      <axis xyz=" 0  1  0" />
      <limit
        lower="${j2_lower_limit}"
        upper="${j2_upper_limit}"
        effort="${j2_effort_limit}"
        velocity="${j2_velocity_limit}"
      />
    </joint>

    <joint name="${prefix}J3" type="revolute">
      <origin xyz=" 0  0  1.15" rpy="0 0 0" />
      <parent link="${prefix}J2_link" />
      <child link="${prefix}J3_link" />
      <axis xyz=" 0 -1  0" />
      <limit
        lower="${j3_lower_limit}"
        upper="${j3_upper_limit}"
        effort="${j3_effort_limit}"
        velocity="${j3_velocity_limit}"
      />
    </joint>

    <joint name="${prefix}J4" type="revolute">
      <origin xyz=" 0  0  .17" rpy="0 0 0" />
      <parent link="${prefix}J3_link" />
      <child link="${prefix}J4_link" />
      <axis xyz="-1  0  0" />
      <limit
        lower="${j4_lower_limit}"
        upper="${j4_upper_limit}"
        effort="${j4_effort_limit}"
        velocity="${j4_velocity_limit}"
      />
    </joint>

    <joint name="${prefix}J5" type="revolute">
      <origin xyz=" 1.295  0  0" rpy="0 0 0" />
      <parent link="${prefix}J4_link" />
      <child link="${prefix}J5_link" />
      <axis xyz=" 0 -1  0" />
      <limit
        lower="${j5_lower_limit}"
        upper="${j5_upper_limit}"
        effort="${j5_effort_limit}"
        velocity="${j5_velocity_limit}"
      />
    </joint>

    <joint name="${prefix}J6" type="revolute">
      <origin xyz=" 0  0  0" rpy="0 0 0" />
      <parent link="${prefix}J5_link" />
      <child link="${prefix}J6_link" />
      <axis xyz="-1  0  0" />
      <limit
        lower="${j6_lower_limit}"
        upper="${j6_upper_limit}"
        effort="${j6_effort_limit}"
        velocity="${j6_velocity_limit}"
      />
    </joint>

    <!-- world coords -->
    <link name="${prefix}wbase" />
    <joint name="${prefix}base_link-wbase" type="fixed">
      <origin xyz=" 0  0  .565" rpy="0 0 0" />
      <parent link="${prefix}base_link" />
      <child link="${prefix}wbase" />
    </joint>

    <!-- flange coords -->
    <link name="${prefix}flange" />
    <joint name="${prefix}J6-flange" type="fixed">
      <origin xyz=" .175  0  0" rpy="0 0 0" />
      <parent link="${prefix}J6_link" />
      <child link="${prefix}flange" />
    </joint>

    <!-- FANUC flange coords -->
    <link name="${prefix}fanuc_flange" />
    <joint name="${prefix}flange-fanuc_flange" type="fixed">
      <origin xyz="0 0 0" rpy="${radians( 180)} ${radians(-90)} ${radians( 0)}" />
      <parent link="${prefix}flange" />
      <child link="${prefix}fanuc_flange" />
    </joint>

    <!-- Attach to parent -->
    <joint name="${prefix}base_joint" type="fixed">
      <xacro:insert_block name="origin" />
      <parent link="${parent}" />
      <child link="${prefix}base_link" />
    </joint>

    <!-- Attach child -->
    <joint name="${prefix}child_joint" type="fixed">
      <origin xyz="0 0 0" rpy="0 0 0" />
      <parent link="${prefix}flange" />
      <child link="${child}" />
    </joint>
  </xacro:macro>
</robot>
