<?xml version="1.0" ?>
<!--
SPDX-FileCopyrightText: 2026, FANUC America Corporation
SPDX-FileCopyrightText: 2026, FANUC CORPORATION
SPDX-License-Identifier: Apache-2.0
-->
<!-- URDF for R-2000/210F-31E -->
<robot xmlns:xacro="http://wiki.ros.org/xacro">
  <xacro:macro
    name="r2000_210f_31e"
    params="prefix=''
            parent
            *origin
            child"
  >

    <xacro:property name="j1_lower_limit" value="${radians(-185)}" />
    <xacro:property name="j2_lower_limit" value="${radians(-60)}" />
    <xacro:property name="j3_lower_limit" value="${radians(-79)}" />
    <xacro:property name="j4_lower_limit" value="${radians(-360)}" />
    <xacro:property name="j5_lower_limit" value="${radians(-125)}" />
    <xacro:property name="j6_lower_limit" value="${radians(-360)}" />

    <xacro:property name="j1_upper_limit" value="${radians(185)}" />
    <xacro:property name="j2_upper_limit" value="${radians(76)}" />
    <xacro:property name="j3_upper_limit" value="${radians(180)}" />
    <xacro:property name="j4_upper_limit" value="${radians(360)}" />
    <xacro:property name="j5_upper_limit" value="${radians(125)}" />
    <xacro:property name="j6_upper_limit" value="${radians(360)}" />

    <xacro:property name="j1_effort_limit" value="20000" />
    <xacro:property name="j2_effort_limit" value="30000" />
    <xacro:property name="j3_effort_limit" value="30000" />
    <xacro:property name="j4_effort_limit" value="5000" />
    <xacro:property name="j5_effort_limit" value="6000" />
    <xacro:property name="j6_effort_limit" value="3000" />

    <xacro:property name="j1_velocity_limit" value="${radians(110)}" />
    <xacro:property name="j2_velocity_limit" value="${radians(95)}" />
    <xacro:property name="j3_velocity_limit" value="${radians(90)}" />
    <xacro:property name="j4_velocity_limit" value="${radians(130)}" />
    <xacro:property name="j5_velocity_limit" value="${radians(130)}" />
    <xacro:property name="j6_velocity_limit" value="${radians(210)}" />

    <!-- links -->
    <link name="${prefix}base_link">
      <visual>
        <origin xyz="0 0 0" rpy="0 0 0" />
        <geometry>
          <mesh
            filename="package://fanuc_r2000_description/meshes/r2000_210f_31e/visual/base.dae"
          />
        </geometry>
      </visual>
      <collision>
        <origin xyz="0 0 0" rpy="0 0 0" />
        <geometry>
          <mesh
            filename="package://fanuc_r2000_description/meshes/r2000_210f_31e/collision/base.stl"
          />
        </geometry>
      </collision>
      <inertial>
        <mass value=" 194" />
        <origin xyz="-.105 -.000066  .144" />
        <inertia
          ixx=" 6.25"
          ixy=" .234"
          ixz="-.164"
          iyy=" 12.3"
          iyz=" .0468"
          izz=" 15.3"
        />
      </inertial>
    </link>

    <link name="${prefix}J1_link">
      <visual>
        <origin xyz="0 0 0" rpy="0 0 0" />
        <geometry>
          <mesh
            filename="package://fanuc_r2000_description/meshes/r2000_210f_31e/visual/j1.dae"
          />
        </geometry>
      </visual>
      <collision>
        <origin xyz="0 0 0" rpy="0 0 0" />
        <geometry>
          <mesh
            filename="package://fanuc_r2000_description/meshes/r2000_210f_31e/collision/j1.stl"
          />
        </geometry>
      </collision>
      <inertial>
        <mass value=" 398" />
        <origin xyz=" .0116  .0854 -.114" />
        <inertia
          ixx=" 23"
          ixy=" 3.93"
          ixz="-.881"
          iyy=" 31"
          iyz="-.747"
          izz=" 37.3"
        />
      </inertial>
    </link>

    <link name="${prefix}J2_link">
      <visual>
        <origin xyz="0 0 0" rpy="0 0 0" />
        <geometry>
          <mesh
            filename="package://fanuc_r2000_description/meshes/r2000_210f_31e/visual/j2.dae"
          />
        </geometry>
      </visual>
      <collision>
        <origin xyz="0 0 0" rpy="0 0 0" />
        <geometry>
          <mesh
            filename="package://fanuc_r2000_description/meshes/r2000_210f_31e/collision/j2.stl"
          />
        </geometry>
      </collision>
      <inertial>
        <mass value=" 328" />
        <origin xyz="-.00533  .266  .484" />
        <inertia
          ixx=" 51.3"
          ixy="-.163"
          ixz="-2.17"
          iyy=" 50.9"
          iyz="-.774"
          izz=" 9.4"
        />
      </inertial>
    </link>

    <link name="${prefix}J3_link">
      <visual>
        <origin xyz="0 0 0" rpy="0 0 0" />
        <geometry>
          <mesh
            filename="package://fanuc_r2000_description/meshes/r2000_210f_31e/visual/j3.dae"
          />
        </geometry>
      </visual>
      <collision>
        <origin xyz="0 0 0" rpy="0 0 0" />
        <geometry>
          <mesh
            filename="package://fanuc_r2000_description/meshes/r2000_210f_31e/collision/j3.stl"
          />
        </geometry>
      </collision>
      <inertial>
        <mass value=" 430" />
        <origin xyz=" .413  .0594  .153" />
        <inertia
          ixx=" 15.7"
          ixy=" 1.72"
          ixz="-4.52"
          iyy=" 84.7"
          iyz="-.19"
          izz=" 87.1"
        />
      </inertial>
    </link>

    <link name="${prefix}J4_link">
      <visual>
        <origin xyz="0 0 0" rpy="0 0 0" />
        <geometry>
          <mesh
            filename="package://fanuc_r2000_description/meshes/r2000_210f_31e/visual/j4.dae"
          />
        </geometry>
      </visual>
      <collision>
        <origin xyz="0 0 0" rpy="0 0 0" />
        <geometry>
          <mesh
            filename="package://fanuc_r2000_description/meshes/r2000_210f_31e/collision/j4.stl"
          />
        </geometry>
      </collision>
      <inertial>
        <mass value=" 12.5" />
        <origin xyz=" 1.6 -.00384  .000000000921" />
        <inertia
          ixx=" .0565"
          ixy=" .00328"
          ixz=" .000000000992"
          iyy=" .144"
          iyz="-.000000000457"
          izz=" .141"
        />
      </inertial>
    </link>

    <link name="${prefix}J5_link">
      <visual>
        <origin xyz="0 0 0" rpy="0 0 0" />
        <geometry>
          <mesh
            filename="package://fanuc_r2000_description/meshes/r2000_210f_31e/visual/j5.dae"
          />
        </geometry>
      </visual>
      <collision>
        <origin xyz="0 0 0" rpy="0 0 0" />
        <geometry>
          <mesh
            filename="package://fanuc_r2000_description/meshes/r2000_210f_31e/collision/j5.stl"
          />
        </geometry>
      </collision>
      <inertial>
        <mass value=" 25" />
        <origin xyz=" .0526 -.02  .0000000207" />
        <inertia
          ixx=" .255"
          ixy="-.0324"
          ixz=" .000000192"
          iyy=" .262"
          iyz="-.000000664"
          izz=" .351"
        />
      </inertial>
    </link>

    <link name="${prefix}J6_link">
      <visual>
        <origin xyz="0 0 0" rpy="0 0 0" />
        <geometry>
          <mesh
            filename="package://fanuc_r2000_description/meshes/r2000_210f_31e/visual/j6.dae"
          />
        </geometry>
      </visual>
      <collision>
        <origin xyz="0 0 0" rpy="0 0 0" />
        <geometry>
          <mesh
            filename="package://fanuc_r2000_description/meshes/r2000_210f_31e/collision/j6.stl"
          />
        </geometry>
      </collision>
      <inertial>
        <mass value=" 2.8" />
        <origin xyz=" .207 -.0000000104  .0000167" />
        <inertia
          ixx=" .0126"
          ixy="-.000000000571"
          ixz=" .000000267"
          iyy=" .00745"
          iyz=" .00000000791"
          izz=" .00746"
        />
      </inertial>
    </link>

    <!-- joints -->
    <joint name="${prefix}J1" type="revolute">
      <origin xyz=" 0  0  .67" rpy="0 0 0" />
      <parent link="${prefix}base_link" />
      <child link="${prefix}J1_link" />
      <axis xyz=" 0  0  1" />
      <limit
        lower="${j1_lower_limit}"
        upper="${j1_upper_limit}"
        effort="${j1_effort_limit}"
        velocity="${j1_velocity_limit}"
      />
    </joint>

    <joint name="${prefix}J2" type="revolute">
      <origin xyz=" .312  0  0" rpy="0 0 0" />
      <parent link="${prefix}J1_link" />
      <child link="${prefix}J2_link" />
      <axis xyz=" 0  1  0" />
      <limit
        lower="${j2_lower_limit}"
        upper="${j2_upper_limit}"
        effort="${j2_effort_limit}"
        velocity="${j2_velocity_limit}"
      />
    </joint>

    <joint name="${prefix}J3" type="revolute">
      <origin xyz=" 0  0  1.075" rpy="0 0 0" />
      <parent link="${prefix}J2_link" />
      <child link="${prefix}J3_link" />
      <axis xyz=" 0 -1  0" />
      <limit
        lower="${j3_lower_limit}"
        upper="${j3_upper_limit}"
        effort="${j3_effort_limit}"
        velocity="${j3_velocity_limit}"
      />
    </joint>

    <joint name="${prefix}J4" type="revolute">
      <origin xyz=" 0  0  .225" rpy="0 0 0" />
      <parent link="${prefix}J3_link" />
      <child link="${prefix}J4_link" />
      <axis xyz="-1  0  0" />
      <limit
        lower="${j4_lower_limit}"
        upper="${j4_upper_limit}"
        effort="${j4_effort_limit}"
        velocity="${j4_velocity_limit}"
      />
    </joint>

    <joint name="${prefix}J5" type="revolute">
      <origin xyz=" 1.73  0  0" rpy="0 0 0" />
      <parent link="${prefix}J4_link" />
      <child link="${prefix}J5_link" />
      <axis xyz=" 0 -1  0" />
      <limit
        lower="${j5_lower_limit}"
        upper="${j5_upper_limit}"
        effort="${j5_effort_limit}"
        velocity="${j5_velocity_limit}"
      />
    </joint>

    <joint name="${prefix}J6" type="revolute">
      <origin xyz=" 0  0  0" rpy="0 0 0" />
      <parent link="${prefix}J5_link" />
      <child link="${prefix}J6_link" />
      <axis xyz="-1  0  0" />
      <limit
        lower="${j6_lower_limit}"
        upper="${j6_upper_limit}"
        effort="${j6_effort_limit}"
        velocity="${j6_velocity_limit}"
      />
    </joint>

    <!-- world coords -->
    <link name="${prefix}wbase" />
    <joint name="${prefix}base_link-wbase" type="fixed">
      <origin xyz=" 0  0  .67" rpy="0 0 0" />
      <parent link="${prefix}base_link" />
      <child link="${prefix}wbase" />
    </joint>

    <!-- flange coords -->
    <link name="${prefix}flange" />
    <joint name="${prefix}J6-flange" type="fixed">
      <origin xyz=" .24  0  0" rpy="0 0 0" />
      <parent link="${prefix}J6_link" />
      <child link="${prefix}flange" />
    </joint>

    <!-- FANUC flange coords -->
    <link name="${prefix}fanuc_flange" />
    <joint name="${prefix}flange-fanuc_flange" type="fixed">
      <origin xyz="0 0 0" rpy="${radians( 180)} ${radians(-90)} ${radians( 0)}" />
      <parent link="${prefix}flange" />
      <child link="${prefix}fanuc_flange" />
    </joint>

    <!-- Attach to parent -->
    <joint name="${prefix}base_joint" type="fixed">
      <xacro:insert_block name="origin" />
      <parent link="${parent}" />
      <child link="${prefix}base_link" />
    </joint>

    <!-- Attach child -->
    <joint name="${prefix}child_joint" type="fixed">
      <origin xyz="0 0 0" rpy="0 0 0" />
      <parent link="${prefix}flange" />
      <child link="${child}" />
    </joint>
  </xacro:macro>
</robot>
