<?xml version="1.0" ?>
<!--
SPDX-FileCopyrightText: 2026, FANUC America Corporation
SPDX-FileCopyrightText: 2026, FANUC CORPORATION
SPDX-License-Identifier: Apache-2.0
-->
<!-- URDF for LR Mate/35-14A (M-20iB/35S) -->
<robot xmlns:xacro="http://wiki.ros.org/xacro">
  <xacro:macro
    name="lrmate35-14a"
    params="prefix=''
            parent
            *origin
            child"
  >

    <xacro:property name="j1_lower_limit" value="${radians(-180)}" />
    <xacro:property name="j2_lower_limit" value="${radians(-100)}" />
    <xacro:property name="j3_lower_limit" value="${radians(-81.5)}" />
    <xacro:property name="j4_lower_limit" value="${radians(-200)}" />
    <xacro:property name="j5_lower_limit" value="${radians(-130)}" />
    <xacro:property name="j6_lower_limit" value="${radians(-270)}" />

    <xacro:property name="j1_upper_limit" value="${radians(180)}" />
    <xacro:property name="j2_upper_limit" value="${radians(140)}" />
    <xacro:property name="j3_upper_limit" value="${radians(220)}" />
    <xacro:property name="j4_upper_limit" value="${radians(200)}" />
    <xacro:property name="j5_upper_limit" value="${radians(130)}" />
    <xacro:property name="j6_upper_limit" value="${radians(270)}" />

    <xacro:property name="j1_effort_limit" value="4000" />
    <xacro:property name="j2_effort_limit" value="7000" />
    <xacro:property name="j3_effort_limit" value="2000" />
    <xacro:property name="j4_effort_limit" value="500" />
    <xacro:property name="j5_effort_limit" value="300" />
    <xacro:property name="j6_effort_limit" value="200" />

    <xacro:property name="j1_velocity_limit" value="${radians(205)}" />
    <xacro:property name="j2_velocity_limit" value="${radians(205)}" />
    <xacro:property name="j3_velocity_limit" value="${radians(260)}" />
    <xacro:property name="j4_velocity_limit" value="${radians(415)}" />
    <xacro:property name="j5_velocity_limit" value="${radians(415)}" />
    <xacro:property name="j6_velocity_limit" value="${radians(880)}" />

    <!-- links -->
    <link name="${prefix}base_link">
      <visual>
        <origin xyz="0 0 0" rpy="0 0 0" />
        <geometry>
          <mesh
            filename="package://fanuc_lrmate_description/meshes/lrmate35-14a/visual/base.dae"
          />
        </geometry>
      </visual>
      <collision>
        <origin xyz="0 0 0" rpy="0 0 0" />
        <geometry>
          <mesh
            filename="package://fanuc_lrmate_description/meshes/lrmate35-14a/collision/base.stl"
          />
        </geometry>
      </collision>
      <inertial>
        <mass value=" 36" />
        <origin xyz="-.0269 -.0000215  .157" />
        <inertia
          ixx=" .616"
          ixy="-.00604"
          ixz="-.0058"
          iyy=" .753"
          iyz="-.00063"
          izz=" .738"
        />
      </inertial>
    </link>

    <link name="${prefix}J1_link">
      <visual>
        <origin xyz="0 0 0" rpy="0 0 0" />
        <geometry>
          <mesh
            filename="package://fanuc_lrmate_description/meshes/lrmate35-14a/visual/j1.dae"
          />
        </geometry>
      </visual>
      <collision>
        <origin xyz="0 0 0" rpy="0 0 0" />
        <geometry>
          <mesh
            filename="package://fanuc_lrmate_description/meshes/lrmate35-14a/collision/j1.stl"
          />
        </geometry>
      </collision>
      <inertial>
        <mass value=" 57.9" />
        <origin xyz=" .0372  .00108 -.101" />
        <inertia
          ixx=" 2.05"
          ixy="-.00376"
          ixz="-.165"
          iyy=" 1.27"
          iyz="-.00429"
          izz=" 1.69"
        />
      </inertial>
    </link>

    <link name="${prefix}J2_link">
      <visual>
        <origin xyz="0 0 0" rpy="0 0 0" />
        <geometry>
          <mesh
            filename="package://fanuc_lrmate_description/meshes/lrmate35-14a/visual/j2.dae"
          />
        </geometry>
      </visual>
      <collision>
        <origin xyz="0 0 0" rpy="0 0 0" />
        <geometry>
          <mesh
            filename="package://fanuc_lrmate_description/meshes/lrmate35-14a/collision/j2.stl"
          />
        </geometry>
      </collision>
      <inertial>
        <mass value=" 78.1" />
        <origin xyz="-.00113 -.000658  .324" />
        <inertia
          ixx=" 5.64"
          ixy="-.00094"
          ixz=" .000886"
          iyy=" 5.06"
          iyz=" .00373"
          izz=" 1.43"
        />
      </inertial>
    </link>

    <link name="${prefix}J3_link">
      <visual>
        <origin xyz="0 0 0" rpy="0 0 0" />
        <geometry>
          <mesh
            filename="package://fanuc_lrmate_description/meshes/lrmate35-14a/visual/j3.dae"
          />
        </geometry>
      </visual>
      <collision>
        <origin xyz="0 0 0" rpy="0 0 0" />
        <geometry>
          <mesh
            filename="package://fanuc_lrmate_description/meshes/lrmate35-14a/collision/j3.stl"
          />
        </geometry>
      </collision>
      <inertial>
        <mass value=" 19" />
        <origin xyz=" .0221 -.00161  .0386" />
        <inertia
          ixx=" .233"
          ixy="-.00579"
          ixz="-.0249"
          iyy=" .258"
          iyz="-.00229"
          izz=" .227"
        />
      </inertial>
    </link>

    <link name="${prefix}J4_link">
      <visual>
        <origin xyz="0 0 0" rpy="0 0 0" />
        <geometry>
          <mesh
            filename="package://fanuc_lrmate_description/meshes/lrmate35-14a/visual/j4.dae"
          />
        </geometry>
      </visual>
      <collision>
        <origin xyz="0 0 0" rpy="0 0 0" />
        <geometry>
          <mesh
            filename="package://fanuc_lrmate_description/meshes/lrmate35-14a/collision/j4.stl"
          />
        </geometry>
      </collision>
      <inertial>
        <mass value=" 12.8" />
        <origin xyz=" .456  .00534 -.00000319" />
        <inertia
          ixx=" .0516"
          ixy=" .00205"
          ixz="-.00000144"
          iyy=" .385"
          iyz=" .00000375"
          izz=" .4"
        />
      </inertial>
    </link>

    <link name="${prefix}J5_link">
      <visual>
        <origin xyz="0 0 0" rpy="0 0 0" />
        <geometry>
          <mesh
            filename="package://fanuc_lrmate_description/meshes/lrmate35-14a/visual/j5.dae"
          />
        </geometry>
      </visual>
      <collision>
        <origin xyz="0 0 0" rpy="0 0 0" />
        <geometry>
          <mesh
            filename="package://fanuc_lrmate_description/meshes/lrmate35-14a/collision/j5.stl"
          />
        </geometry>
      </collision>
      <inertial>
        <mass value=" 1.24" />
        <origin xyz=" .0173  .00272  .0000418" />
        <inertia
          ixx=" .00201"
          ixy=" .0000313"
          ixz=" .000000159"
          iyy=" .00296"
          iyz="-.000000564"
          izz=" .00287"
        />
      </inertial>
    </link>

    <link name="${prefix}J6_link">
      <visual>
        <origin xyz="0 0 0" rpy="0 0 0" />
        <geometry>
          <mesh
            filename="package://fanuc_lrmate_description/meshes/lrmate35-14a/visual/j6.dae"
          />
        </geometry>
      </visual>
      <collision>
        <origin xyz="0 0 0" rpy="0 0 0" />
        <geometry>
          <mesh
            filename="package://fanuc_lrmate_description/meshes/lrmate35-14a/collision/j6.stl"
          />
        </geometry>
      </collision>
      <inertial>
        <mass value=" .0265" />
        <origin xyz=" .0936 -3.11E-18  2.17E-17" />
        <inertia
          ixx=" .0000107"
          ixy=" 1.93E-20"
          ixz=" 1.06E-19"
          iyy=" .00000563"
          iyz="-4.38E-21"
          izz=" .00000563"
        />
      </inertial>
    </link>

    <!-- joints -->
    <joint name="${prefix}J1" type="revolute">
      <origin xyz=" 0  0  .65" rpy="0 0 0" />
      <parent link="${prefix}base_link" />
      <child link="${prefix}J1_link" />
      <axis xyz=" 0  0  1" />
      <limit
        lower="${j1_lower_limit}"
        upper="${j1_upper_limit}"
        effort="${j1_effort_limit}"
        velocity="${j1_velocity_limit}"
      />
    </joint>

    <joint name="${prefix}J2" type="revolute">
      <origin xyz=" .075  0  0" rpy="0 0 0" />
      <parent link="${prefix}J1_link" />
      <child link="${prefix}J2_link" />
      <axis xyz=" 0  1  0" />
      <limit
        lower="${j2_lower_limit}"
        upper="${j2_upper_limit}"
        effort="${j2_effort_limit}"
        velocity="${j2_velocity_limit}"
      />
    </joint>

    <joint name="${prefix}J3" type="revolute">
      <origin xyz=" 0  0  .637" rpy="0 0 0" />
      <parent link="${prefix}J2_link" />
      <child link="${prefix}J3_link" />
      <axis xyz=" 0 -1  0" />
      <limit
        lower="${j3_lower_limit}"
        upper="${j3_upper_limit}"
        effort="${j3_effort_limit}"
        velocity="${j3_velocity_limit}"
      />
    </joint>

    <joint name="${prefix}J4" type="revolute">
      <origin xyz=" 0  0  .12" rpy="0 0 0" />
      <parent link="${prefix}J3_link" />
      <child link="${prefix}J4_link" />
      <axis xyz="-1  0  0" />
      <limit
        lower="${j4_lower_limit}"
        upper="${j4_upper_limit}"
        effort="${j4_effort_limit}"
        velocity="${j4_velocity_limit}"
      />
    </joint>

    <joint name="${prefix}J5" type="revolute">
      <origin xyz=" .723  0  0" rpy="0 0 0" />
      <parent link="${prefix}J4_link" />
      <child link="${prefix}J5_link" />
      <axis xyz=" 0 -1  0" />
      <limit
        lower="${j5_lower_limit}"
        upper="${j5_upper_limit}"
        effort="${j5_effort_limit}"
        velocity="${j5_velocity_limit}"
      />
    </joint>

    <joint name="${prefix}J6" type="revolute">
      <origin xyz=" 0  0  0" rpy="0 0 0" />
      <parent link="${prefix}J5_link" />
      <child link="${prefix}J6_link" />
      <axis xyz="-1  0  0" />
      <limit
        lower="${j6_lower_limit}"
        upper="${j6_upper_limit}"
        effort="${j6_effort_limit}"
        velocity="${j6_velocity_limit}"
      />
    </joint>

    <!-- world coords -->
    <link name="${prefix}wbase" />
    <joint name="${prefix}base_link-wbase" type="fixed">
      <origin xyz=" 0  0  .65" rpy="0 0 0" />
      <parent link="${prefix}base_link" />
      <child link="${prefix}wbase" />
    </joint>

    <!-- flange coords -->
    <link name="${prefix}flange" />
    <joint name="${prefix}J6-flange" type="fixed">
      <origin xyz=" .1  0  0" rpy="0 0 0" />
      <parent link="${prefix}J6_link" />
      <child link="${prefix}flange" />
    </joint>

    <!-- FANUC flange coords -->
    <link name="${prefix}fanuc_flange" />
    <joint name="${prefix}flange-fanuc_flange" type="fixed">
      <origin xyz="0 0 0" rpy="${radians( 180)} ${radians(-90)} ${radians( 0)}" />
      <parent link="${prefix}flange" />
      <child link="${prefix}fanuc_flange" />
    </joint>

    <!-- Attach to parent -->
    <joint name="${prefix}base_joint" type="fixed">
      <xacro:insert_block name="origin" />
      <parent link="${parent}" />
      <child link="${prefix}base_link" />
    </joint>

    <!-- Attach child -->
    <joint name="${prefix}child_joint" type="fixed">
      <origin xyz="0 0 0" rpy="0 0 0" />
      <parent link="${prefix}flange" />
      <child link="${child}" />
    </joint>
  </xacro:macro>
</robot>
