<?xml version="1.0" ?>
<!--
SPDX-FileCopyrightText: 2026, FANUC America Corporation
SPDX-FileCopyrightText: 2026, FANUC CORPORATION
SPDX-License-Identifier: Apache-2.0
-->
<!-- URDF for LR Mate/7-7D Food/Clean(LR Mate 200iD/7C) -->
<robot xmlns:xacro="http://wiki.ros.org/xacro">
  <xacro:macro
    name="lrmate200id7c"
    params="prefix=''
            parent
            *origin
            child"
  >

    <xacro:property name="j1_lower_limit" value="${radians(-180)}" />
    <xacro:property name="j2_lower_limit" value="${radians(-100)}" />
    <xacro:property name="j3_lower_limit" value="${radians(-70)}" />
    <xacro:property name="j4_lower_limit" value="${radians(-190)}" />
    <xacro:property name="j5_lower_limit" value="${radians(-125)}" />
    <xacro:property name="j6_lower_limit" value="${radians(-360)}" />

    <xacro:property name="j1_upper_limit" value="${radians(180)}" />
    <xacro:property name="j2_upper_limit" value="${radians(145)}" />
    <xacro:property name="j3_upper_limit" value="${radians(205)}" />
    <xacro:property name="j4_upper_limit" value="${radians(190)}" />
    <xacro:property name="j5_upper_limit" value="${radians(125)}" />
    <xacro:property name="j6_upper_limit" value="${radians(360)}" />

    <xacro:property name="j1_effort_limit" value="500" />
    <xacro:property name="j2_effort_limit" value="500" />
    <xacro:property name="j3_effort_limit" value="200" />
    <xacro:property name="j4_effort_limit" value="70" />
    <xacro:property name="j5_effort_limit" value="40" />
    <xacro:property name="j6_effort_limit" value="20" />

    <xacro:property name="j1_velocity_limit" value="${radians(450)}" />
    <xacro:property name="j2_velocity_limit" value="${radians(380)}" />
    <xacro:property name="j3_velocity_limit" value="${radians(520)}" />
    <xacro:property name="j4_velocity_limit" value="${radians(550)}" />
    <xacro:property name="j5_velocity_limit" value="${radians(545)}" />
    <xacro:property name="j6_velocity_limit" value="${radians(1000)}" />

    <!-- links -->
    <link name="${prefix}base_link">
      <visual>
        <origin xyz="0 0 0" rpy="0 0 0" />
        <geometry>
          <mesh
            filename="package://fanuc_lrmate_description/meshes/lrmate200id7c/visual/base.dae"
          />
        </geometry>
      </visual>
      <collision>
        <origin xyz="0 0 0" rpy="0 0 0" />
        <geometry>
          <mesh
            filename="package://fanuc_lrmate_description/meshes/lrmate200id7c/collision/base.stl"
          />
        </geometry>
      </collision>
      <inertial>
        <mass value=" 5.28" />
        <origin xyz="-.0146 -.000342  .0796" />
        <inertia
          ixx=" .025"
          ixy="-.000573"
          ixz=" .000296"
          iyy=" .0305"
          iyz="-.000121"
          izz=" .0321"
        />
      </inertial>
    </link>

    <link name="${prefix}J1_link">
      <visual>
        <origin xyz="0 0 0" rpy="0 0 0" />
        <geometry>
          <mesh
            filename="package://fanuc_lrmate_description/meshes/lrmate200id7c/visual/j1.dae"
          />
        </geometry>
      </visual>
      <collision>
        <origin xyz="0 0 0" rpy="0 0 0" />
        <geometry>
          <mesh
            filename="package://fanuc_lrmate_description/meshes/lrmate200id7c/collision/j1.stl"
          />
        </geometry>
      </collision>
      <inertial>
        <mass value=" 5.61" />
        <origin xyz=" .0287  .000102 -.0547" />
        <inertia
          ixx=" .0416"
          ixy=" .0000238"
          ixz="-.0055"
          iyy=" .0302"
          iyz=" .000121"
          izz=" .0321"
        />
      </inertial>
    </link>

    <link name="${prefix}J2_link">
      <visual>
        <origin xyz="0 0 0" rpy="0 0 0" />
        <geometry>
          <mesh
            filename="package://fanuc_lrmate_description/meshes/lrmate200id7c/visual/j2.dae"
          />
        </geometry>
      </visual>
      <collision>
        <origin xyz="0 0 0" rpy="0 0 0" />
        <geometry>
          <mesh
            filename="package://fanuc_lrmate_description/meshes/lrmate200id7c/collision/j2.stl"
          />
        </geometry>
      </collision>
      <inertial>
        <mass value=" 9.02" />
        <origin xyz="-.00271 -.000976  .159" />
        <inertia
          ixx=" .158"
          ixy=" .0000334"
          ixz=" .000153"
          iyy=" .136"
          iyz="-.00108"
          izz=" .0428"
        />
      </inertial>
    </link>

    <link name="${prefix}J3_link">
      <visual>
        <origin xyz="0 0 0" rpy="0 0 0" />
        <geometry>
          <mesh
            filename="package://fanuc_lrmate_description/meshes/lrmate200id7c/visual/j3.dae"
          />
        </geometry>
      </visual>
      <collision>
        <origin xyz="0 0 0" rpy="0 0 0" />
        <geometry>
          <mesh
            filename="package://fanuc_lrmate_description/meshes/lrmate200id7c/collision/j3.stl"
          />
        </geometry>
      </collision>
      <inertial>
        <mass value=" 2.15" />
        <origin xyz=" .00887 -.0000626  .0171" />
        <inertia
          ixx=" .00583"
          ixy="-.0000458"
          ixz="-.00062"
          iyy=" .00664"
          iyz="-.0000459"
          izz=" .00667"
        />
      </inertial>
    </link>

    <link name="${prefix}J4_link">
      <visual>
        <origin xyz="0 0 0" rpy="0 0 0" />
        <geometry>
          <mesh
            filename="package://fanuc_lrmate_description/meshes/lrmate200id7c/visual/j4.dae"
          />
        </geometry>
      </visual>
      <collision>
        <origin xyz="0 0 0" rpy="0 0 0" />
        <geometry>
          <mesh
            filename="package://fanuc_lrmate_description/meshes/lrmate200id7c/collision/j4.stl"
          />
        </geometry>
      </collision>
      <inertial>
        <mass value=" 2.41" />
        <origin xyz=" .223  .00356  .00215" />
        <inertia
          ixx=" .00394"
          ixy=" .00000026"
          ixz=" .0000723"
          iyy=" .017"
          iyz="-.00000945"
          izz=" .017"
        />
      </inertial>
    </link>

    <link name="${prefix}J5_link">
      <visual>
        <origin xyz="0 0 0" rpy="0 0 0" />
        <geometry>
          <mesh
            filename="package://fanuc_lrmate_description/meshes/lrmate200id7c/visual/j5.dae"
          />
        </geometry>
      </visual>
      <collision>
        <origin xyz="0 0 0" rpy="0 0 0" />
        <geometry>
          <mesh
            filename="package://fanuc_lrmate_description/meshes/lrmate200id7c/collision/j5.stl"
          />
        </geometry>
      </collision>
      <inertial>
        <mass value=" .501" />
        <origin xyz=" .0236  .00233 -.00000699" />
        <inertia
          ixx=" .000391"
          ixy=" .0000229"
          ixz="-.0000000238"
          iyy=" .000782"
          iyz="-.0000000285"
          izz=" .000741"
        />
      </inertial>
    </link>

    <link name="${prefix}J6_link">
      <visual>
        <origin xyz="0 0 0" rpy="0 0 0" />
        <geometry>
          <mesh
            filename="package://fanuc_lrmate_description/meshes/lrmate200id7c/visual/j6.dae"
          />
        </geometry>
      </visual>
      <collision>
        <origin xyz="0 0 0" rpy="0 0 0" />
        <geometry>
          <mesh
            filename="package://fanuc_lrmate_description/meshes/lrmate200id7c/collision/j6.stl"
          />
        </geometry>
      </collision>
      <inertial>
        <mass value=" .021" />
        <origin xyz=" .0836 -3.24E-19 -1.22E-18" />
        <inertia
          ixx=" .00000504"
          ixy=" 1.85E-21"
          ixz="-4.72E-21"
          iyy=" .00000296"
          iyz=" 4.98E-22"
          izz=" .00000296"
        />
      </inertial>
    </link>

    <!-- joints -->
    <joint name="${prefix}J1" type="revolute">
      <origin xyz=" 0  0  .33" rpy="0 0 0" />
      <parent link="${prefix}base_link" />
      <child link="${prefix}J1_link" />
      <axis xyz=" 0  0  1" />
      <limit
        lower="${j1_lower_limit}"
        upper="${j1_upper_limit}"
        effort="${j1_effort_limit}"
        velocity="${j1_velocity_limit}"
      />
    </joint>

    <joint name="${prefix}J2" type="revolute">
      <origin xyz=" .05  0  0" rpy="0 0 0" />
      <parent link="${prefix}J1_link" />
      <child link="${prefix}J2_link" />
      <axis xyz=" 0  1  0" />
      <limit
        lower="${j2_lower_limit}"
        upper="${j2_upper_limit}"
        effort="${j2_effort_limit}"
        velocity="${j2_velocity_limit}"
      />
    </joint>

    <joint name="${prefix}J3" type="revolute">
      <origin xyz=" 0  0  .33" rpy="0 0 0" />
      <parent link="${prefix}J2_link" />
      <child link="${prefix}J3_link" />
      <axis xyz=" 0 -1  0" />
      <limit
        lower="${j3_lower_limit}"
        upper="${j3_upper_limit}"
        effort="${j3_effort_limit}"
        velocity="${j3_velocity_limit}"
      />
    </joint>

    <joint name="${prefix}J4" type="revolute">
      <origin xyz=" 0  0  .035" rpy="0 0 0" />
      <parent link="${prefix}J3_link" />
      <child link="${prefix}J4_link" />
      <axis xyz="-1  0  0" />
      <limit
        lower="${j4_lower_limit}"
        upper="${j4_upper_limit}"
        effort="${j4_effort_limit}"
        velocity="${j4_velocity_limit}"
      />
    </joint>

    <joint name="${prefix}J5" type="revolute">
      <origin xyz=" .335  0  0" rpy="0 0 0" />
      <parent link="${prefix}J4_link" />
      <child link="${prefix}J5_link" />
      <axis xyz=" 0 -1  0" />
      <limit
        lower="${j5_lower_limit}"
        upper="${j5_upper_limit}"
        effort="${j5_effort_limit}"
        velocity="${j5_velocity_limit}"
      />
    </joint>

    <joint name="${prefix}J6" type="revolute">
      <origin xyz=" 0  0  0" rpy="0 0 0" />
      <parent link="${prefix}J5_link" />
      <child link="${prefix}J6_link" />
      <axis xyz="-1  0  0" />
      <limit
        lower="${j6_lower_limit}"
        upper="${j6_upper_limit}"
        effort="${j6_effort_limit}"
        velocity="${j6_velocity_limit}"
      />
    </joint>

    <!-- world coords -->
    <link name="${prefix}wbase" />
    <joint name="${prefix}base_link-wbase" type="fixed">
      <origin xyz=" 0  0  .33" rpy="0 0 0" />
      <parent link="${prefix}base_link" />
      <child link="${prefix}wbase" />
    </joint>

    <!-- flange coords -->
    <link name="${prefix}flange" />
    <joint name="${prefix}J6-flange" type="fixed">
      <origin xyz=" .09  0  0" rpy="0 0 0" />
      <parent link="${prefix}J6_link" />
      <child link="${prefix}flange" />
    </joint>

    <!-- FANUC flange coords -->
    <link name="${prefix}fanuc_flange" />
    <joint name="${prefix}flange-fanuc_flange" type="fixed">
      <origin xyz="0 0 0" rpy="${radians( 180)} ${radians(-90)} ${radians( 0)}" />
      <parent link="${prefix}flange" />
      <child link="${prefix}fanuc_flange" />
    </joint>

    <!-- Attach to parent -->
    <joint name="${prefix}base_joint" type="fixed">
      <xacro:insert_block name="origin" />
      <parent link="${parent}" />
      <child link="${prefix}base_link" />
    </joint>

    <!-- Attach child -->
    <joint name="${prefix}child_joint" type="fixed">
      <origin xyz="0 0 0" rpy="0 0 0" />
      <parent link="${prefix}flange" />
      <child link="${child}" />
    </joint>
  </xacro:macro>
</robot>
