<?xml version="1.0" ?>
<!--
SPDX-FileCopyrightText: 2026, FANUC America Corporation
SPDX-FileCopyrightText: 2026, FANUC CORPORATION
SPDX-License-Identifier: Apache-2.0
-->
<!-- URDF for LR Mate/7-7D Wash (LR Mate 200iD/7WE) -->
<robot xmlns:xacro="http://wiki.ros.org/xacro">
  <xacro:macro
    name="lrmate200id7we"
    params="prefix=''
            parent
            *origin
            child"
  >

    <xacro:property name="j1_lower_limit" value="${radians(-180)}" />
    <xacro:property name="j2_lower_limit" value="${radians(-100)}" />
    <xacro:property name="j3_lower_limit" value="${radians(-70)}" />
    <xacro:property name="j4_lower_limit" value="${radians(-190)}" />
    <xacro:property name="j5_lower_limit" value="${radians(-125)}" />
    <xacro:property name="j6_lower_limit" value="${radians(-360)}" />

    <xacro:property name="j1_upper_limit" value="${radians(180)}" />
    <xacro:property name="j2_upper_limit" value="${radians(145)}" />
    <xacro:property name="j3_upper_limit" value="${radians(205)}" />
    <xacro:property name="j4_upper_limit" value="${radians(190)}" />
    <xacro:property name="j5_upper_limit" value="${radians(125)}" />
    <xacro:property name="j6_upper_limit" value="${radians(360)}" />

    <xacro:property name="j1_effort_limit" value="500" />
    <xacro:property name="j2_effort_limit" value="500" />
    <xacro:property name="j3_effort_limit" value="300" />
    <xacro:property name="j4_effort_limit" value="70" />
    <xacro:property name="j5_effort_limit" value="40" />
    <xacro:property name="j6_effort_limit" value="20" />

    <xacro:property name="j1_velocity_limit" value="${radians(450)}" />
    <xacro:property name="j2_velocity_limit" value="${radians(380)}" />
    <xacro:property name="j3_velocity_limit" value="${radians(410)}" />
    <xacro:property name="j4_velocity_limit" value="${radians(550)}" />
    <xacro:property name="j5_velocity_limit" value="${radians(545)}" />
    <xacro:property name="j6_velocity_limit" value="${radians(1000)}" />

    <!-- links -->
    <link name="${prefix}base_link">
      <visual>
        <origin xyz="0 0 0" rpy="0 0 0" />
        <geometry>
          <mesh
            filename="package://fanuc_lrmate_description/meshes/lrmate200id7we/visual/base.dae"
          />
        </geometry>
      </visual>
      <collision>
        <origin xyz="0 0 0" rpy="0 0 0" />
        <geometry>
          <mesh
            filename="package://fanuc_lrmate_description/meshes/lrmate200id7we/collision/base.stl"
          />
        </geometry>
      </collision>
      <inertial>
        <mass value=" 5.89" />
        <origin xyz="-.019 -.000897  .0796" />
        <inertia
          ixx=" .0275"
          ixy="-.000994"
          ixz=" .000302"
          iyy=" .0361"
          iyz="-.00012"
          izz=" .0379"
        />
      </inertial>
    </link>

    <link name="${prefix}J1_link">
      <visual>
        <origin xyz="0 0 0" rpy="0 0 0" />
        <geometry>
          <mesh
            filename="package://fanuc_lrmate_description/meshes/lrmate200id7we/visual/j1.dae"
          />
        </geometry>
      </visual>
      <collision>
        <origin xyz="0 0 0" rpy="0 0 0" />
        <geometry>
          <mesh
            filename="package://fanuc_lrmate_description/meshes/lrmate200id7we/collision/j1.stl"
          />
        </geometry>
      </collision>
      <inertial>
        <mass value=" 6.03" />
        <origin xyz=" .0287  .000102 -.0547" />
        <inertia
          ixx=" .0447"
          ixy=" .0000255"
          ixz="-.00591"
          iyy=" .0325"
          iyz=" .00013"
          izz=" .0345"
        />
      </inertial>
    </link>

    <link name="${prefix}J2_link">
      <visual>
        <origin xyz="0 0 0" rpy="0 0 0" />
        <geometry>
          <mesh
            filename="package://fanuc_lrmate_description/meshes/lrmate200id7we/visual/j2.dae"
          />
        </geometry>
      </visual>
      <collision>
        <origin xyz="0 0 0" rpy="0 0 0" />
        <geometry>
          <mesh
            filename="package://fanuc_lrmate_description/meshes/lrmate200id7we/collision/j2.stl"
          />
        </geometry>
      </collision>
      <inertial>
        <mass value=" 9.69" />
        <origin xyz="-.00271 -.000976  .159" />
        <inertia
          ixx=" .17"
          ixy=" .0000359"
          ixz=" .000165"
          iyy=" .146"
          iyz="-.00116"
          izz=" .0459"
        />
      </inertial>
    </link>

    <link name="${prefix}J3_link">
      <visual>
        <origin xyz="0 0 0" rpy="0 0 0" />
        <geometry>
          <mesh
            filename="package://fanuc_lrmate_description/meshes/lrmate200id7we/visual/j3.dae"
          />
        </geometry>
      </visual>
      <collision>
        <origin xyz="0 0 0" rpy="0 0 0" />
        <geometry>
          <mesh
            filename="package://fanuc_lrmate_description/meshes/lrmate200id7we/collision/j3.stl"
          />
        </geometry>
      </collision>
      <inertial>
        <mass value=" 2.31" />
        <origin xyz=" .00887 -.0000626  .0171" />
        <inertia
          ixx=" .00626"
          ixy="-.0000492"
          ixz="-.000666"
          iyy=" .00713"
          iyz="-.0000493"
          izz=" .00717"
        />
      </inertial>
    </link>

    <link name="${prefix}J4_link">
      <visual>
        <origin xyz="0 0 0" rpy="0 0 0" />
        <geometry>
          <mesh
            filename="package://fanuc_lrmate_description/meshes/lrmate200id7we/visual/j4.dae"
          />
        </geometry>
      </visual>
      <collision>
        <origin xyz="0 0 0" rpy="0 0 0" />
        <geometry>
          <mesh
            filename="package://fanuc_lrmate_description/meshes/lrmate200id7we/collision/j4.stl"
          />
        </geometry>
      </collision>
      <inertial>
        <mass value=" 2.59" />
        <origin xyz=" .223  .00356  .00215" />
        <inertia
          ixx=" .00423"
          ixy=" .000000279"
          ixz=" .0000776"
          iyy=" .0183"
          iyz="-.0000101"
          izz=" .0183"
        />
      </inertial>
    </link>

    <link name="${prefix}J5_link">
      <visual>
        <origin xyz="0 0 0" rpy="0 0 0" />
        <geometry>
          <mesh
            filename="package://fanuc_lrmate_description/meshes/lrmate200id7we/visual/j5.dae"
          />
        </geometry>
      </visual>
      <collision>
        <origin xyz="0 0 0" rpy="0 0 0" />
        <geometry>
          <mesh
            filename="package://fanuc_lrmate_description/meshes/lrmate200id7we/collision/j5.stl"
          />
        </geometry>
      </collision>
      <inertial>
        <mass value=" .477" />
        <origin xyz=" .0177  .0025 -.00000419" />
        <inertia
          ixx=" .000363"
          ixy=" .00002"
          ixz="-.0000000224"
          iyy=" .000644"
          iyz="-.0000000184"
          izz=" .000603"
        />
      </inertial>
    </link>

    <link name="${prefix}J6_link">
      <visual>
        <origin xyz="0 0 0" rpy="0 0 0" />
        <geometry>
          <mesh
            filename="package://fanuc_lrmate_description/meshes/lrmate200id7we/visual/j6.dae"
          />
        </geometry>
      </visual>
      <collision>
        <origin xyz="0 0 0" rpy="0 0 0" />
        <geometry>
          <mesh
            filename="package://fanuc_lrmate_description/meshes/lrmate200id7we/collision/j6.stl"
          />
        </geometry>
      </collision>
      <inertial>
        <mass value=" .0144" />
        <origin xyz=" .074  2.26E-18  3.35E-18" />
        <inertia
          ixx=" .00000295"
          ixy=" 5.39E-21"
          ixz=" 2.91E-21"
          iyy=" .00000164"
          iyz="-1.17E-22"
          izz=" .00000164"
        />
      </inertial>
    </link>

    <!-- joints -->
    <joint name="${prefix}J1" type="revolute">
      <origin xyz=" 0  0  .33" rpy="0 0 0" />
      <parent link="${prefix}base_link" />
      <child link="${prefix}J1_link" />
      <axis xyz=" 0  0  1" />
      <limit
        lower="${j1_lower_limit}"
        upper="${j1_upper_limit}"
        effort="${j1_effort_limit}"
        velocity="${j1_velocity_limit}"
      />
    </joint>

    <joint name="${prefix}J2" type="revolute">
      <origin xyz=" .05  0  0" rpy="0 0 0" />
      <parent link="${prefix}J1_link" />
      <child link="${prefix}J2_link" />
      <axis xyz=" 0  1  0" />
      <limit
        lower="${j2_lower_limit}"
        upper="${j2_upper_limit}"
        effort="${j2_effort_limit}"
        velocity="${j2_velocity_limit}"
      />
    </joint>

    <joint name="${prefix}J3" type="revolute">
      <origin xyz=" 0  0  .33" rpy="0 0 0" />
      <parent link="${prefix}J2_link" />
      <child link="${prefix}J3_link" />
      <axis xyz=" 0 -1  0" />
      <limit
        lower="${j3_lower_limit}"
        upper="${j3_upper_limit}"
        effort="${j3_effort_limit}"
        velocity="${j3_velocity_limit}"
      />
    </joint>

    <joint name="${prefix}J4" type="revolute">
      <origin xyz=" 0  0  .035" rpy="0 0 0" />
      <parent link="${prefix}J3_link" />
      <child link="${prefix}J4_link" />
      <axis xyz="-1  0  0" />
      <limit
        lower="${j4_lower_limit}"
        upper="${j4_upper_limit}"
        effort="${j4_effort_limit}"
        velocity="${j4_velocity_limit}"
      />
    </joint>

    <joint name="${prefix}J5" type="revolute">
      <origin xyz=" .335  0  0" rpy="0 0 0" />
      <parent link="${prefix}J4_link" />
      <child link="${prefix}J5_link" />
      <axis xyz=" 0 -1  0" />
      <limit
        lower="${j5_lower_limit}"
        upper="${j5_upper_limit}"
        effort="${j5_effort_limit}"
        velocity="${j5_velocity_limit}"
      />
    </joint>

    <joint name="${prefix}J6" type="revolute">
      <origin xyz=" 0  0  0" rpy="0 0 0" />
      <parent link="${prefix}J5_link" />
      <child link="${prefix}J6_link" />
      <axis xyz="-1  0  0" />
      <limit
        lower="${j6_lower_limit}"
        upper="${j6_upper_limit}"
        effort="${j6_effort_limit}"
        velocity="${j6_velocity_limit}"
      />
    </joint>

    <!-- world coords -->
    <link name="${prefix}wbase" />
    <joint name="${prefix}base_link-wbase" type="fixed">
      <origin xyz=" 0  0  .33" rpy="0 0 0" />
      <parent link="${prefix}base_link" />
      <child link="${prefix}wbase" />
    </joint>

    <!-- flange coords -->
    <link name="${prefix}flange" />
    <joint name="${prefix}J6-flange" type="fixed">
      <origin xyz=" .08  0  0" rpy="0 0 0" />
      <parent link="${prefix}J6_link" />
      <child link="${prefix}flange" />
    </joint>

    <!-- FANUC flange coords -->
    <link name="${prefix}fanuc_flange" />
    <joint name="${prefix}flange-fanuc_flange" type="fixed">
      <origin xyz="0 0 0" rpy="${radians( 180)} ${radians(-90)} ${radians( 0)}" />
      <parent link="${prefix}flange" />
      <child link="${prefix}fanuc_flange" />
    </joint>

    <!-- Attach to parent -->
    <joint name="${prefix}base_joint" type="fixed">
      <xacro:insert_block name="origin" />
      <parent link="${parent}" />
      <child link="${prefix}base_link" />
    </joint>

    <!-- Attach child -->
    <joint name="${prefix}child_joint" type="fixed">
      <origin xyz="0 0 0" rpy="0 0 0" />
      <parent link="${prefix}flange" />
      <child link="${child}" />
    </joint>
  </xacro:macro>
</robot>
