<?xml version="1.0" ?>
<!--
SPDX-FileCopyrightText: 2026, FANUC America Corporation
SPDX-FileCopyrightText: 2026, FANUC CORPORATION
SPDX-License-Identifier: Apache-2.0
-->
<!-- URDF for R-1000/130F-22A(R-1000iA/130F) -->
<robot xmlns:xacro="http://wiki.ros.org/xacro">
  <xacro:macro
    name="r1000ia_130f"
    params="prefix=''
            parent
            *origin
            child"
  >

    <xacro:property name="j1_lower_limit" value="${radians(-180)}" />
    <xacro:property name="j2_lower_limit" value="${radians(-90)}" />
    <xacro:property name="j3_lower_limit" value="${radians(-82)}" />
    <xacro:property name="j4_lower_limit" value="${radians(-360)}" />
    <xacro:property name="j5_lower_limit" value="${radians(-125)}" />
    <xacro:property name="j6_lower_limit" value="${radians(-360)}" />

    <xacro:property name="j1_upper_limit" value="${radians(180)}" />
    <xacro:property name="j2_upper_limit" value="${radians(155)}" />
    <xacro:property name="j3_upper_limit" value="${radians(140)}" />
    <xacro:property name="j4_upper_limit" value="${radians(360)}" />
    <xacro:property name="j5_upper_limit" value="${radians(125)}" />
    <xacro:property name="j6_upper_limit" value="${radians(360)}" />

    <xacro:property name="j1_effort_limit" value="9000" />
    <xacro:property name="j2_effort_limit" value="30000" />
    <xacro:property name="j3_effort_limit" value="8000" />
    <xacro:property name="j4_effort_limit" value="3000" />
    <xacro:property name="j5_effort_limit" value="3000" />
    <xacro:property name="j6_effort_limit" value="2000" />

    <xacro:property name="j1_velocity_limit" value="${radians(130)}" />
    <xacro:property name="j2_velocity_limit" value="${radians(110)}" />
    <xacro:property name="j3_velocity_limit" value="${radians(120)}" />
    <xacro:property name="j4_velocity_limit" value="${radians(170)}" />
    <xacro:property name="j5_velocity_limit" value="${radians(170)}" />
    <xacro:property name="j6_velocity_limit" value="${radians(250)}" />

    <!-- links -->
    <link name="${prefix}base_link">
      <visual>
        <origin xyz="0 0 0" rpy="0 0 0" />
        <geometry>
          <mesh
            filename="package://fanuc_r1000ia_description/meshes/r1000ia_130f/visual/base.dae"
          />
        </geometry>
      </visual>
      <collision>
        <origin xyz="0 0 0" rpy="0 0 0" />
        <geometry>
          <mesh
            filename="package://fanuc_r1000ia_description/meshes/r1000ia_130f/collision/base.stl"
          />
        </geometry>
      </collision>
      <inertial>
        <mass value=" 141" />
        <origin xyz="-.146  .00115  .117" />
        <inertia
          ixx=" 2.76"
          ixy=" .0638"
          ixz="-.158"
          iyy=" 6.88"
          iyz=" .0137"
          izz=" 8.33"
        />
      </inertial>
    </link>

    <link name="${prefix}J1_link">
      <visual>
        <origin xyz="0 0 0" rpy="0 0 0" />
        <geometry>
          <mesh
            filename="package://fanuc_r1000ia_description/meshes/r1000ia_130f/visual/j1.dae"
          />
        </geometry>
      </visual>
      <collision>
        <origin xyz="0 0 0" rpy="0 0 0" />
        <geometry>
          <mesh
            filename="package://fanuc_r1000ia_description/meshes/r1000ia_130f/collision/j1.stl"
          />
        </geometry>
      </collision>
      <inertial>
        <mass value=" 196" />
        <origin xyz=" .14 -.0172 -.0368" />
        <inertia
          ixx=" 5.69"
          ixy=" .046"
          ixz="-.247"
          iyy=" 7.72"
          iyz=" .484"
          izz=" 8.51"
        />
      </inertial>
    </link>

    <link name="${prefix}J2_link">
      <visual>
        <origin xyz="0 0 0" rpy="0 0 0" />
        <geometry>
          <mesh
            filename="package://fanuc_r1000ia_description/meshes/r1000ia_130f/visual/j2.dae"
          />
        </geometry>
      </visual>
      <collision>
        <origin xyz="0 0 0" rpy="0 0 0" />
        <geometry>
          <mesh
            filename="package://fanuc_r1000ia_description/meshes/r1000ia_130f/collision/j2.stl"
          />
        </geometry>
      </collision>
      <inertial>
        <mass value=" 110" />
        <origin xyz=" .00598  .148  .394" />
        <inertia
          ixx=" 10.3"
          ixy="-.00252"
          ixz=" .00625"
          iyy=" 10.7"
          iyz="-.167"
          izz=" 1.03"
        />
      </inertial>
    </link>

    <link name="${prefix}J3_link">
      <visual>
        <origin xyz="0 0 0" rpy="0 0 0" />
        <geometry>
          <mesh
            filename="package://fanuc_r1000ia_description/meshes/r1000ia_130f/visual/j3.dae"
          />
        </geometry>
      </visual>
      <collision>
        <origin xyz="0 0 0" rpy="0 0 0" />
        <geometry>
          <mesh
            filename="package://fanuc_r1000ia_description/meshes/r1000ia_130f/collision/j3.stl"
          />
        </geometry>
      </collision>
      <inertial>
        <mass value=" 205" />
        <origin xyz=" .238  .0114  .137" />
        <inertia
          ixx=" 5.21"
          ixy="-.0632"
          ixz="-1.89"
          iyy=" 13.3"
          iyz="-.196"
          izz=" 12.4"
        />
      </inertial>
    </link>

    <link name="${prefix}J4_link">
      <visual>
        <origin xyz="0 0 0" rpy="0 0 0" />
        <geometry>
          <mesh
            filename="package://fanuc_r1000ia_description/meshes/r1000ia_130f/visual/j4.dae"
          />
        </geometry>
      </visual>
      <collision>
        <origin xyz="0 0 0" rpy="0 0 0" />
        <geometry>
          <mesh
            filename="package://fanuc_r1000ia_description/meshes/r1000ia_130f/collision/j4.stl"
          />
        </geometry>
      </collision>
      <inertial>
        <mass value=" 7.84" />
        <origin xyz=" .929 -.00482  1.99E-16" />
        <inertia
          ixx=" .0229"
          ixy=" .00214"
          ixz=" 2.97E-15"
          iyy=" .0503"
          iyz=" .00000000000454"
          izz=" .0478"
        />
      </inertial>
    </link>

    <link name="${prefix}J5_link">
      <visual>
        <origin xyz="0 0 0" rpy="0 0 0" />
        <geometry>
          <mesh
            filename="package://fanuc_r1000ia_description/meshes/r1000ia_130f/visual/j5.dae"
          />
        </geometry>
      </visual>
      <collision>
        <origin xyz="0 0 0" rpy="0 0 0" />
        <geometry>
          <mesh
            filename="package://fanuc_r1000ia_description/meshes/r1000ia_130f/collision/j5.stl"
          />
        </geometry>
      </collision>
      <inertial>
        <mass value=" 15.3" />
        <origin xyz=" .0473 -.0132 -.00000000107" />
        <inertia
          ixx=" .0851"
          ixy="-.0118"
          ixz="-.000000000371"
          iyy=" .105"
          iyz="-.000000000953"
          izz=" .127"
        />
      </inertial>
    </link>

    <link name="${prefix}J6_link">
      <visual>
        <origin xyz="0 0 0" rpy="0 0 0" />
        <geometry>
          <mesh
            filename="package://fanuc_r1000ia_description/meshes/r1000ia_130f/visual/j6.dae"
          />
        </geometry>
      </visual>
      <collision>
        <origin xyz="0 0 0" rpy="0 0 0" />
        <geometry>
          <mesh
            filename="package://fanuc_r1000ia_description/meshes/r1000ia_130f/collision/j6.stl"
          />
        </geometry>
      </collision>
      <inertial>
        <mass value=" .423" />
        <origin xyz=" .181  .00000000234  .000171" />
        <inertia
          ixx=" .000843"
          ixy="-.00000000000497"
          ixz="-.00000046"
          iyy=" .000431"
          iyz=" .000000000056"
          izz=" .000435"
        />
      </inertial>
    </link>

    <!-- joints -->
    <joint name="${prefix}J1" type="revolute">
      <origin xyz=" 0  0  .45" rpy="0 0 0" />
      <parent link="${prefix}base_link" />
      <child link="${prefix}J1_link" />
      <axis xyz=" 0  0  1" />
      <limit
        lower="${j1_lower_limit}"
        upper="${j1_upper_limit}"
        effort="${j1_effort_limit}"
        velocity="${j1_velocity_limit}"
      />
    </joint>

    <joint name="${prefix}J2" type="revolute">
      <origin xyz=" .32  0  0" rpy="0 0 0" />
      <parent link="${prefix}J1_link" />
      <child link="${prefix}J2_link" />
      <axis xyz=" 0  1  0" />
      <limit
        lower="${j2_lower_limit}"
        upper="${j2_upper_limit}"
        effort="${j2_effort_limit}"
        velocity="${j2_velocity_limit}"
      />
    </joint>

    <joint name="${prefix}J3" type="revolute">
      <origin xyz=" 0  0  .87" rpy="0 0 0" />
      <parent link="${prefix}J2_link" />
      <child link="${prefix}J3_link" />
      <axis xyz=" 0 -1  0" />
      <limit
        lower="${j3_lower_limit}"
        upper="${j3_upper_limit}"
        effort="${j3_effort_limit}"
        velocity="${j3_velocity_limit}"
      />
    </joint>

    <joint name="${prefix}J4" type="revolute">
      <origin xyz=" 0  0  .225" rpy="0 0 0" />
      <parent link="${prefix}J3_link" />
      <child link="${prefix}J4_link" />
      <axis xyz="-1  0  0" />
      <limit
        lower="${j4_lower_limit}"
        upper="${j4_upper_limit}"
        effort="${j4_effort_limit}"
        velocity="${j4_velocity_limit}"
      />
    </joint>

    <joint name="${prefix}J5" type="revolute">
      <origin xyz=" 1.015  0  0" rpy="0 0 0" />
      <parent link="${prefix}J4_link" />
      <child link="${prefix}J5_link" />
      <axis xyz=" 0 -1  0" />
      <limit
        lower="${j5_lower_limit}"
        upper="${j5_upper_limit}"
        effort="${j5_effort_limit}"
        velocity="${j5_velocity_limit}"
      />
    </joint>

    <joint name="${prefix}J6" type="revolute">
      <origin xyz=" 0  0  0" rpy="0 0 0" />
      <parent link="${prefix}J5_link" />
      <child link="${prefix}J6_link" />
      <axis xyz="-1  0  0" />
      <limit
        lower="${j6_lower_limit}"
        upper="${j6_upper_limit}"
        effort="${j6_effort_limit}"
        velocity="${j6_velocity_limit}"
      />
    </joint>

    <!-- world coords -->
    <link name="${prefix}wbase" />
    <joint name="${prefix}base_link-wbase" type="fixed">
      <origin xyz=" 0  0  .45" rpy="0 0 0" />
      <parent link="${prefix}base_link" />
      <child link="${prefix}wbase" />
    </joint>

    <!-- flange coords -->
    <link name="${prefix}flange" />
    <joint name="${prefix}J6-flange" type="fixed">
      <origin xyz=" .19  0  0" rpy="0 0 0" />
      <parent link="${prefix}J6_link" />
      <child link="${prefix}flange" />
    </joint>

    <!-- FANUC flange coords -->
    <link name="${prefix}fanuc_flange" />
    <joint name="${prefix}flange-fanuc_flange" type="fixed">
      <origin xyz="0 0 0" rpy="${radians( 180)} ${radians(-90)} ${radians( 0)}" />
      <parent link="${prefix}flange" />
      <child link="${prefix}fanuc_flange" />
    </joint>

    <!-- Attach to parent -->
    <joint name="${prefix}base_joint" type="fixed">
      <xacro:insert_block name="origin" />
      <parent link="${parent}" />
      <child link="${prefix}base_link" />
    </joint>

    <!-- Attach child -->
    <joint name="${prefix}child_joint" type="fixed">
      <origin xyz="0 0 0" rpy="0 0 0" />
      <parent link="${prefix}flange" />
      <child link="${child}" />
    </joint>
  </xacro:macro>
</robot>
